Workbook

Sheet DATA RAW
A1: CRO | B1: Wilayah | C1: Nama Kebun/PT HO | D1: NAME TAG KEBUN | E1: LUASAN | F1: Kebutuhan Tenaga Panen | G1: TK PANEN MEI | H1: TK PANEN JUNI | I1: TK PANEN JULI | J1: TK PANEN AGUSTUS | K1: TARGET TK PANEN JULI | L1: TARGET TK PANEN AGUSTUS
A2: CRO 1 | B2: Regional Aceh | C2: PT Bintang Permata Alue Waki | D2: PT-BPA-01 | E2: {=XLOOKUP(C2,'DATA TK PANEN'!D:D,'DATA TK PANEN'!H:H)} -> 69.57 | F2: =IFERROR(__xludf.DUMMYFUNCTION("XLOOKUP(C2, IMPORTRANGE(""https://docs.google.com/spreadsheets/d/1RJrFMGUC-XijmB6MWr0bUJNzuN7BM1j8R_D0vOt0s8I/edit?usp=sharing"", ""'Master Data TK V0.2 (AUTO)'!F6:F""), IMPORTRANGE(""https://docs.google.com/spreadsheets/d/1RJrFMGUC-XijmB6MWr0bUJNzuN7BM1j"&"8R_D0vOt0s8I/edit?usp=sharing"", ""'Master Data TK V0.2 (AUTO)'!S6:S""))"),"-") -> - | G2: =IFERROR(__xludf.DUMMYFUNCTION("XLOOKUP($C2, IMPORTRANGE(""https://docs.google.com/spreadsheets/d/1RJrFMGUC-XijmB6MWr0bUJNzuN7BM1j8R_D0vOt0s8I/edit?usp=sharing"", ""'Master Data TK V0.2 (AUTO)'!F6:F""), IMPORTRANGE(""https://docs.google.com/spreadsheets/d/1RJrFMGUC-XijmB6MWr0bUJNzuN7BM1"&"j8R_D0vOt0s8I/edit?usp=sharing"", ""'Master Data TK V0.2 (AUTO)'!T6:T""))"),"-") -> - | H2: =IFERROR(__xludf.DUMMYFUNCTION("XLOOKUP($C2, IMPORTRANGE(""https://docs.google.com/spreadsheets/d/1RJrFMGUC-XijmB6MWr0bUJNzuN7BM1j8R_D0vOt0s8I/edit?usp=sharing"", ""'Master Data TK V0.2 (AUTO)'!F6:F""), IMPORTRANGE(""https://docs.google.com/spreadsheets/d/1RJrFMGUC-XijmB6MWr0bUJNzuN7BM1"&"j8R_D0vOt0s8I/edit?usp=sharing"", ""'Master Data TK V0.2 (AUTO)'!V6:V""))"),"") | K2: =IFERROR(__xludf.DUMMYFUNCTION("XLOOKUP($C2, IMPORTRANGE(""https://docs.google.com/spreadsheets/d/1RJrFMGUC-XijmB6MWr0bUJNzuN7BM1j8R_D0vOt0s8I/edit?usp=sharing"", ""'Master Data TK V0.2 (AUTO)'!F6:F""), IMPORTRANGE(""https://docs.google.com/spreadsheets/d/1RJrFMGUC-XijmB6MWr0bUJNzuN7BM1"&"j8R_D0vOt0s8I/edit?usp=sharing"", ""'Master Data TK V0.2 (AUTO)'!W6:W""))"),0.0) -> 0 | L2: =IFERROR(__xludf.DUMMYFUNCTION("XLOOKUP($C2, IMPORTRANGE(""https://docs.google.com/spreadsheets/d/1RJrFMGUC-XijmB6MWr0bUJNzuN7BM1j8R_D0vOt0s8I/edit?usp=sharing"", ""'Master Data TK V0.2 (AUTO)'!F6:F""), IMPORTRANGE(""https://docs.google.com/spreadsheets/d/1RJrFMGUC-XijmB6MWr0bUJNzuN7BM1"&"j8R_D0vOt0s8I/edit?usp=sharing"", ""'Master Data TK V0.2 (AUTO)'!X6:X""))"),0.0) -> 0
A3: CRO 1 | B3: Regional Aceh | C3: PT Dharmasawita Nusantara | D3: PT-DNH-01 | E3: {=XLOOKUP(C3,'DATA TK PANEN'!D:D,'DATA TK PANEN'!H:H)} -> 22 | F3: =IFERROR(__xludf.DUMMYFUNCTION("XLOOKUP(C3, IMPORTRANGE(""https://docs.google.com/spreadsheets/d/1RJrFMGUC-XijmB6MWr0bUJNzuN7BM1j8R_D0vOt0s8I/edit?usp=sharing"", ""'Master Data TK V0.2 (AUTO)'!F6:F""), IMPORTRANGE(""https://docs.google.com/spreadsheets/d/1RJrFMGUC-XijmB6MWr0bUJNzuN7BM1j"&"8R_D0vOt0s8I/edit?usp=sharing"", ""'Master Data TK V0.2 (AUTO)'!S6:S""))"),"-") -> - | G3: =IFERROR(__xludf.DUMMYFUNCTION("XLOOKUP($C3, IMPORTRANGE(""https://docs.google.com/spreadsheets/d/1RJrFMGUC-XijmB6MWr0bUJNzuN7BM1j8R_D0vOt0s8I/edit?usp=sharing"", ""'Master Data TK V0.2 (AUTO)'!F6:F""), IMPORTRANGE(""https://docs.google.com/spreadsheets/d/1RJrFMGUC-XijmB6MWr0bUJNzuN7BM1"&"j8R_D0vOt0s8I/edit?usp=sharing"", ""'Master Data TK V0.2 (AUTO)'!T6:T""))"),"-") -> - | H3: =IFERROR(__xludf.DUMMYFUNCTION("XLOOKUP($C3, IMPORTRANGE(""https://docs.google.com/spreadsheets/d/1RJrFMGUC-XijmB6MWr0bUJNzuN7BM1j8R_D0vOt0s8I/edit?usp=sharing"", ""'Master Data TK V0.2 (AUTO)'!F6:F""), IMPORTRANGE(""https://docs.google.com/spreadsheets/d/1RJrFMGUC-XijmB6MWr0bUJNzuN7BM1"&"j8R_D0vOt0s8I/edit?usp=sharing"", ""'Master Data TK V0.2 (AUTO)'!V6:V""))"),"") | K3: =IFERROR(__xludf.DUMMYFUNCTION("XLOOKUP($C3, IMPORTRANGE(""https://docs.google.com/spreadsheets/d/1RJrFMGUC-XijmB6MWr0bUJNzuN7BM1j8R_D0vOt0s8I/edit?usp=sharing"", ""'Master Data TK V0.2 (AUTO)'!F6:F""), IMPORTRANGE(""https://docs.google.com/spreadsheets/d/1RJrFMGUC-XijmB6MWr0bUJNzuN7BM1"&"j8R_D0vOt0s8I/edit?usp=sharing"", ""'Master Data TK V0.2 (AUTO)'!W6:W""))"),0.0) -> 0 | L3: =IFERROR(__xludf.DUMMYFUNCTION("XLOOKUP($C3, IMPORTRANGE(""https://docs.google.com/spreadsheets/d/1RJrFMGUC-XijmB6MWr0bUJNzuN7BM1j8R_D0vOt0s8I/edit?usp=sharing"", ""'Master Data TK V0.2 (AUTO)'!F6:F""), IMPORTRANGE(""https://docs.google.com/spreadsheets/d/1RJrFMGUC-XijmB6MWr0bUJNzuN7BM1"&"j8R_D0vOt0s8I/edit?usp=sharing"", ""'Master Data TK V0.2 (AUTO)'!X6:X""))"),0.0) -> 0
A4: CRO 1 | B4: Regional Aceh | C4: PT Global Sawit Semesta | D4: PT-GSS-01 | E4: {=XLOOKUP(C4,'DATA TK PANEN'!D:D,'DATA TK PANEN'!H:H)} -> 346.2 | F4: =IFERROR(__xludf.DUMMYFUNCTION("XLOOKUP(C4, IMPORTRANGE(""https://docs.google.com/spreadsheets/d/1RJrFMGUC-XijmB6MWr0bUJNzuN7BM1j8R_D0vOt0s8I/edit?usp=sharing"", ""'Master Data TK V0.2 (AUTO)'!F6:F""), IMPORTRANGE(""https://docs.google.com/spreadsheets/d/1RJrFMGUC-XijmB6MWr0bUJNzuN7BM1j"&"8R_D0vOt0s8I/edit?usp=sharing"", ""'Master Data TK V0.2 (AUTO)'!S6:S""))"),"-") -> - | G4: =IFERROR(__xludf.DUMMYFUNCTION("XLOOKUP($C4, IMPORTRANGE(""https://docs.google.com/spreadsheets/d/1RJrFMGUC-XijmB6MWr0bUJNzuN7BM1j8R_D0vOt0s8I/edit?usp=sharing"", ""'Master Data TK V0.2 (AUTO)'!F6:F""), IMPORTRANGE(""https://docs.google.com/spreadsheets/d/1RJrFMGUC-XijmB6MWr0bUJNzuN7BM1"&"j8R_D0vOt0s8I/edit?usp=sharing"", ""'Master Data TK V0.2 (AUTO)'!T6:T""))"),"-") -> - | H4: =IFERROR(__xludf.DUMMYFUNCTION("XLOOKUP($C4, IMPORTRANGE(""https://docs.google.com/spreadsheets/d/1RJrFMGUC-XijmB6MWr0bUJNzuN7BM1j8R_D0vOt0s8I/edit?usp=sharing"", ""'Master Data TK V0.2 (AUTO)'!F6:F""), IMPORTRANGE(""https://docs.google.com/spreadsheets/d/1RJrFMGUC-XijmB6MWr0bUJNzuN7BM1"&"j8R_D0vOt0s8I/edit?usp=sharing"", ""'Master Data TK V0.2 (AUTO)'!V6:V""))"),"") | K4: =IFERROR(__xludf.DUMMYFUNCTION("XLOOKUP($C4, IMPORTRANGE(""https://docs.google.com/spreadsheets/d/1RJrFMGUC-XijmB6MWr0bUJNzuN7BM1j8R_D0vOt0s8I/edit?usp=sharing"", ""'Master Data TK V0.2 (AUTO)'!F6:F""), IMPORTRANGE(""https://docs.google.com/spreadsheets/d/1RJrFMGUC-XijmB6MWr0bUJNzuN7BM1"&"j8R_D0vOt0s8I/edit?usp=sharing"", ""'Master Data TK V0.2 (AUTO)'!W6:W""))"),0.0) -> 0 | L4: =IFERROR(__xludf.DUMMYFUNCTION("XLOOKUP($C4, IMPORTRANGE(""https://docs.google.com/spreadsheets/d/1RJrFMGUC-XijmB6MWr0bUJNzuN7BM1j8R_D0vOt0s8I/edit?usp=sharing"", ""'Master Data TK V0.2 (AUTO)'!F6:F""), IMPORTRANGE(""https://docs.google.com/spreadsheets/d/1RJrFMGUC-XijmB6MWr0bUJNzuN7BM1"&"j8R_D0vOt0s8I/edit?usp=sharing"", ""'Master Data TK V0.2 (AUTO)'!X6:X""))"),0.0) -> 0
A5: CRO 1 | B5: Regional Aceh | C5: PT Mestika Prima Lestari Indah | D5: PT-MPL-02 | E5: {=XLOOKUP(C5,'DATA TK PANEN'!D:D,'DATA TK PANEN'!H:H)} -> 77.89 | F5: =IFERROR(__xludf.DUMMYFUNCTION("XLOOKUP(C5, IMPORTRANGE(""https://docs.google.com/spreadsheets/d/1RJrFMGUC-XijmB6MWr0bUJNzuN7BM1j8R_D0vOt0s8I/edit?usp=sharing"", ""'Master Data TK V0.2 (AUTO)'!F6:F""), IMPORTRANGE(""https://docs.google.com/spreadsheets/d/1RJrFMGUC-XijmB6MWr0bUJNzuN7BM1j"&"8R_D0vOt0s8I/edit?usp=sharing"", ""'Master Data TK V0.2 (AUTO)'!S6:S""))"),5.0) -> 5 | G5: =IFERROR(__xludf.DUMMYFUNCTION("XLOOKUP($C5, IMPORTRANGE(""https://docs.google.com/spreadsheets/d/1RJrFMGUC-XijmB6MWr0bUJNzuN7BM1j8R_D0vOt0s8I/edit?usp=sharing"", ""'Master Data TK V0.2 (AUTO)'!F6:F""), IMPORTRANGE(""https://docs.google.com/spreadsheets/d/1RJrFMGUC-XijmB6MWr0bUJNzuN7BM1"&"j8R_D0vOt0s8I/edit?usp=sharing"", ""'Master Data TK V0.2 (AUTO)'!T6:T""))"),5.0) -> 5 | H5: =IFERROR(__xludf.DUMMYFUNCTION("XLOOKUP($C5, IMPORTRANGE(""https://docs.google.com/spreadsheets/d/1RJrFMGUC-XijmB6MWr0bUJNzuN7BM1j8R_D0vOt0s8I/edit?usp=sharing"", ""'Master Data TK V0.2 (AUTO)'!F6:F""), IMPORTRANGE(""https://docs.google.com/spreadsheets/d/1RJrFMGUC-XijmB6MWr0bUJNzuN7BM1"&"j8R_D0vOt0s8I/edit?usp=sharing"", ""'Master Data TK V0.2 (AUTO)'!V6:V""))"),5.0) -> 5 | K5: =IFERROR(__xludf.DUMMYFUNCTION("XLOOKUP($C5, IMPORTRANGE(""https://docs.google.com/spreadsheets/d/1RJrFMGUC-XijmB6MWr0bUJNzuN7BM1j8R_D0vOt0s8I/edit?usp=sharing"", ""'Master Data TK V0.2 (AUTO)'!F6:F""), IMPORTRANGE(""https://docs.google.com/spreadsheets/d/1RJrFMGUC-XijmB6MWr0bUJNzuN7BM1"&"j8R_D0vOt0s8I/edit?usp=sharing"", ""'Master Data TK V0.2 (AUTO)'!W6:W""))"),0.0) -> 0 | L5: =IFERROR(__xludf.DUMMYFUNCTION("XLOOKUP($C5, IMPORTRANGE(""https://docs.google.com/spreadsheets/d/1RJrFMGUC-XijmB6MWr0bUJNzuN7BM1j8R_D0vOt0s8I/edit?usp=sharing"", ""'Master Data TK V0.2 (AUTO)'!F6:F""), IMPORTRANGE(""https://docs.google.com/spreadsheets/d/1RJrFMGUC-XijmB6MWr0bUJNzuN7BM1"&"j8R_D0vOt0s8I/edit?usp=sharing"", ""'Master Data TK V0.2 (AUTO)'!X6:X""))"),0.0) -> 0
A6: CRO 1 | B6: Regional Aceh | C6: PT Perkebunan Dan Pertanian Sumber Asih | D6: PT-PDP-01 | E6: {=XLOOKUP(C6,'DATA TK PANEN'!D:D,'DATA TK PANEN'!H:H)} -> 155.07 | F6: =IFERROR(__xludf.DUMMYFUNCTION("XLOOKUP(C6, IMPORTRANGE(""https://docs.google.com/spreadsheets/d/1RJrFMGUC-XijmB6MWr0bUJNzuN7BM1j8R_D0vOt0s8I/edit?usp=sharing"", ""'Master Data TK V0.2 (AUTO)'!F6:F""), IMPORTRANGE(""https://docs.google.com/spreadsheets/d/1RJrFMGUC-XijmB6MWr0bUJNzuN7BM1j"&"8R_D0vOt0s8I/edit?usp=sharing"", ""'Master Data TK V0.2 (AUTO)'!S6:S""))"),9.0) -> 9 | G6: =IFERROR(__xludf.DUMMYFUNCTION("XLOOKUP($C6, IMPORTRANGE(""https://docs.google.com/spreadsheets/d/1RJrFMGUC-XijmB6MWr0bUJNzuN7BM1j8R_D0vOt0s8I/edit?usp=sharing"", ""'Master Data TK V0.2 (AUTO)'!F6:F""), IMPORTRANGE(""https://docs.google.com/spreadsheets/d/1RJrFMGUC-XijmB6MWr0bUJNzuN7BM1"&"j8R_D0vOt0s8I/edit?usp=sharing"", ""'Master Data TK V0.2 (AUTO)'!T6:T""))"),7.0) -> 7 | H6: =IFERROR(__xludf.DUMMYFUNCTION("XLOOKUP($C6, IMPORTRANGE(""https://docs.google.com/spreadsheets/d/1RJrFMGUC-XijmB6MWr0bUJNzuN7BM1j8R_D0vOt0s8I/edit?usp=sharing"", ""'Master Data TK V0.2 (AUTO)'!F6:F""), IMPORTRANGE(""https://docs.google.com/spreadsheets/d/1RJrFMGUC-XijmB6MWr0bUJNzuN7BM1"&"j8R_D0vOt0s8I/edit?usp=sharing"", ""'Master Data TK V0.2 (AUTO)'!V6:V""))"),8.0) -> 8 | K6: =IFERROR(__xludf.DUMMYFUNCTION("XLOOKUP($C6, IMPORTRANGE(""https://docs.google.com/spreadsheets/d/1RJrFMGUC-XijmB6MWr0bUJNzuN7BM1j8R_D0vOt0s8I/edit?usp=sharing"", ""'Master Data TK V0.2 (AUTO)'!F6:F""), IMPORTRANGE(""https://docs.google.com/spreadsheets/d/1RJrFMGUC-XijmB6MWr0bUJNzuN7BM1"&"j8R_D0vOt0s8I/edit?usp=sharing"", ""'Master Data TK V0.2 (AUTO)'!W6:W""))"),1.0) -> 1 | L6: =IFERROR(__xludf.DUMMYFUNCTION("XLOOKUP($C6, IMPORTRANGE(""https://docs.google.com/spreadsheets/d/1RJrFMGUC-XijmB6MWr0bUJNzuN7BM1j8R_D0vOt0s8I/edit?usp=sharing"", ""'Master Data TK V0.2 (AUTO)'!F6:F""), IMPORTRANGE(""https://docs.google.com/spreadsheets/d/1RJrFMGUC-XijmB6MWr0bUJNzuN7BM1"&"j8R_D0vOt0s8I/edit?usp=sharing"", ""'Master Data TK V0.2 (AUTO)'!X6:X""))"),0.0) -> 0
A7: CRO 1 | B7: Regional Aceh | C7: PT Sisirau | D7: PT-SIS-02 | E7: {=XLOOKUP(C7,'DATA TK PANEN'!D:D,'DATA TK PANEN'!H:H)} -> 60.54 | F7: =IFERROR(__xludf.DUMMYFUNCTION("XLOOKUP(C7, IMPORTRANGE(""https://docs.google.com/spreadsheets/d/1RJrFMGUC-XijmB6MWr0bUJNzuN7BM1j8R_D0vOt0s8I/edit?usp=sharing"", ""'Master Data TK V0.2 (AUTO)'!F6:F""), IMPORTRANGE(""https://docs.google.com/spreadsheets/d/1RJrFMGUC-XijmB6MWr0bUJNzuN7BM1j"&"8R_D0vOt0s8I/edit?usp=sharing"", ""'Master Data TK V0.2 (AUTO)'!S6:S""))"),"-") -> - | G7: =IFERROR(__xludf.DUMMYFUNCTION("XLOOKUP($C7, IMPORTRANGE(""https://docs.google.com/spreadsheets/d/1RJrFMGUC-XijmB6MWr0bUJNzuN7BM1j8R_D0vOt0s8I/edit?usp=sharing"", ""'Master Data TK V0.2 (AUTO)'!F6:F""), IMPORTRANGE(""https://docs.google.com/spreadsheets/d/1RJrFMGUC-XijmB6MWr0bUJNzuN7BM1"&"j8R_D0vOt0s8I/edit?usp=sharing"", ""'Master Data TK V0.2 (AUTO)'!T6:T""))"),"-") -> - | H7: =IFERROR(__xludf.DUMMYFUNCTION("XLOOKUP($C7, IMPORTRANGE(""https://docs.google.com/spreadsheets/d/1RJrFMGUC-XijmB6MWr0bUJNzuN7BM1j8R_D0vOt0s8I/edit?usp=sharing"", ""'Master Data TK V0.2 (AUTO)'!F6:F""), IMPORTRANGE(""https://docs.google.com/spreadsheets/d/1RJrFMGUC-XijmB6MWr0bUJNzuN7BM1"&"j8R_D0vOt0s8I/edit?usp=sharing"", ""'Master Data TK V0.2 (AUTO)'!V6:V""))"),"") | K7: =IFERROR(__xludf.DUMMYFUNCTION("XLOOKUP($C7, IMPORTRANGE(""https://docs.google.com/spreadsheets/d/1RJrFMGUC-XijmB6MWr0bUJNzuN7BM1j8R_D0vOt0s8I/edit?usp=sharing"", ""'Master Data TK V0.2 (AUTO)'!F6:F""), IMPORTRANGE(""https://docs.google.com/spreadsheets/d/1RJrFMGUC-XijmB6MWr0bUJNzuN7BM1"&"j8R_D0vOt0s8I/edit?usp=sharing"", ""'Master Data TK V0.2 (AUTO)'!W6:W""))"),0.0) -> 0 | L7: =IFERROR(__xludf.DUMMYFUNCTION("XLOOKUP($C7, IMPORTRANGE(""https://docs.google.com/spreadsheets/d/1RJrFMGUC-XijmB6MWr0bUJNzuN7BM1j8R_D0vOt0s8I/edit?usp=sharing"", ""'Master Data TK V0.2 (AUTO)'!F6:F""), IMPORTRANGE(""https://docs.google.com/spreadsheets/d/1RJrFMGUC-XijmB6MWr0bUJNzuN7BM1"&"j8R_D0vOt0s8I/edit?usp=sharing"", ""'Master Data TK V0.2 (AUTO)'!X6:X""))"),0.0) -> 0
A8: CRO 1 | B8: Regional Aceh | C8: PT Teunggulon Raya | D8: PT-TRE-01 | E8: {=XLOOKUP(C8,'DATA TK PANEN'!D:D,'DATA TK PANEN'!H:H)} -> 15.51 | F8: =IFERROR(__xludf.DUMMYFUNCTION("XLOOKUP(C8, IMPORTRANGE(""https://docs.google.com/spreadsheets/d/1RJrFMGUC-XijmB6MWr0bUJNzuN7BM1j8R_D0vOt0s8I/edit?usp=sharing"", ""'Master Data TK V0.2 (AUTO)'!F6:F""), IMPORTRANGE(""https://docs.google.com/spreadsheets/d/1RJrFMGUC-XijmB6MWr0bUJNzuN7BM1j"&"8R_D0vOt0s8I/edit?usp=sharing"", ""'Master Data TK V0.2 (AUTO)'!S6:S""))"),"-") -> - | G8: =IFERROR(__xludf.DUMMYFUNCTION("XLOOKUP($C8, IMPORTRANGE(""https://docs.google.com/spreadsheets/d/1RJrFMGUC-XijmB6MWr0bUJNzuN7BM1j8R_D0vOt0s8I/edit?usp=sharing"", ""'Master Data TK V0.2 (AUTO)'!F6:F""), IMPORTRANGE(""https://docs.google.com/spreadsheets/d/1RJrFMGUC-XijmB6MWr0bUJNzuN7BM1"&"j8R_D0vOt0s8I/edit?usp=sharing"", ""'Master Data TK V0.2 (AUTO)'!T6:T""))"),"-") -> - | H8: =IFERROR(__xludf.DUMMYFUNCTION("XLOOKUP($C8, IMPORTRANGE(""https://docs.google.com/spreadsheets/d/1RJrFMGUC-XijmB6MWr0bUJNzuN7BM1j8R_D0vOt0s8I/edit?usp=sharing"", ""'Master Data TK V0.2 (AUTO)'!F6:F""), IMPORTRANGE(""https://docs.google.com/spreadsheets/d/1RJrFMGUC-XijmB6MWr0bUJNzuN7BM1"&"j8R_D0vOt0s8I/edit?usp=sharing"", ""'Master Data TK V0.2 (AUTO)'!V6:V""))"),"") | K8: =IFERROR(__xludf.DUMMYFUNCTION("XLOOKUP($C8, IMPORTRANGE(""https://docs.google.com/spreadsheets/d/1RJrFMGUC-XijmB6MWr0bUJNzuN7BM1j8R_D0vOt0s8I/edit?usp=sharing"", ""'Master Data TK V0.2 (AUTO)'!F6:F""), IMPORTRANGE(""https://docs.google.com/spreadsheets/d/1RJrFMGUC-XijmB6MWr0bUJNzuN7BM1"&"j8R_D0vOt0s8I/edit?usp=sharing"", ""'Master Data TK V0.2 (AUTO)'!W6:W""))"),0.0) -> 0 | L8: =IFERROR(__xludf.DUMMYFUNCTION("XLOOKUP($C8, IMPORTRANGE(""https://docs.google.com/spreadsheets/d/1RJrFMGUC-XijmB6MWr0bUJNzuN7BM1j8R_D0vOt0s8I/edit?usp=sharing"", ""'Master Data TK V0.2 (AUTO)'!F6:F""), IMPORTRANGE(""https://docs.google.com/spreadsheets/d/1RJrFMGUC-XijmB6MWr0bUJNzuN7BM1"&"j8R_D0vOt0s8I/edit?usp=sharing"", ""'Master Data TK V0.2 (AUTO)'!X6:X""))"),0.0) -> 0
A9: CRO 1 | B9: Regional Aceh | C9: PT Watu Gede Utama | D9: PT-WGU-01 | E9: {=XLOOKUP(C9,'DATA TK PANEN'!D:D,'DATA TK PANEN'!H:H)} -> 510.39 | F9: =IFERROR(__xludf.DUMMYFUNCTION("XLOOKUP(C9, IMPORTRANGE(""https://docs.google.com/spreadsheets/d/1RJrFMGUC-XijmB6MWr0bUJNzuN7BM1j8R_D0vOt0s8I/edit?usp=sharing"", ""'Master Data TK V0.2 (AUTO)'!F6:F""), IMPORTRANGE(""https://docs.google.com/spreadsheets/d/1RJrFMGUC-XijmB6MWr0bUJNzuN7BM1j"&"8R_D0vOt0s8I/edit?usp=sharing"", ""'Master Data TK V0.2 (AUTO)'!S6:S""))"),"-") -> - | G9: =IFERROR(__xludf.DUMMYFUNCTION("XLOOKUP($C9, IMPORTRANGE(""https://docs.google.com/spreadsheets/d/1RJrFMGUC-XijmB6MWr0bUJNzuN7BM1j8R_D0vOt0s8I/edit?usp=sharing"", ""'Master Data TK V0.2 (AUTO)'!F6:F""), IMPORTRANGE(""https://docs.google.com/spreadsheets/d/1RJrFMGUC-XijmB6MWr0bUJNzuN7BM1"&"j8R_D0vOt0s8I/edit?usp=sharing"", ""'Master Data TK V0.2 (AUTO)'!T6:T""))"),"-") -> - | H9: =IFERROR(__xludf.DUMMYFUNCTION("XLOOKUP($C9, IMPORTRANGE(""https://docs.google.com/spreadsheets/d/1RJrFMGUC-XijmB6MWr0bUJNzuN7BM1j8R_D0vOt0s8I/edit?usp=sharing"", ""'Master Data TK V0.2 (AUTO)'!F6:F""), IMPORTRANGE(""https://docs.google.com/spreadsheets/d/1RJrFMGUC-XijmB6MWr0bUJNzuN7BM1"&"j8R_D0vOt0s8I/edit?usp=sharing"", ""'Master Data TK V0.2 (AUTO)'!V6:V""))"),"") | K9: =IFERROR(__xludf.DUMMYFUNCTION("XLOOKUP($C9, IMPORTRANGE(""https://docs.google.com/spreadsheets/d/1RJrFMGUC-XijmB6MWr0bUJNzuN7BM1j8R_D0vOt0s8I/edit?usp=sharing"", ""'Master Data TK V0.2 (AUTO)'!F6:F""), IMPORTRANGE(""https://docs.google.com/spreadsheets/d/1RJrFMGUC-XijmB6MWr0bUJNzuN7BM1"&"j8R_D0vOt0s8I/edit?usp=sharing"", ""'Master Data TK V0.2 (AUTO)'!W6:W""))"),0.0) -> 0 | L9: =IFERROR(__xludf.DUMMYFUNCTION("XLOOKUP($C9, IMPORTRANGE(""https://docs.google.com/spreadsheets/d/1RJrFMGUC-XijmB6MWr0bUJNzuN7BM1j8R_D0vOt0s8I/edit?usp=sharing"", ""'Master Data TK V0.2 (AUTO)'!F6:F""), IMPORTRANGE(""https://docs.google.com/spreadsheets/d/1RJrFMGUC-XijmB6MWr0bUJNzuN7BM1"&"j8R_D0vOt0s8I/edit?usp=sharing"", ""'Master Data TK V0.2 (AUTO)'!X6:X""))"),0.0) -> 0
A10: CRO 1 | B10: Regional Sumut 1 | C10: Kelompok Tani Mahoni Rimbun | D10: KT-MRA-01 | E10: {=XLOOKUP(C10,'DATA TK PANEN'!D:D,'DATA TK PANEN'!H:H)} -> Tidak Ditemukan | F10: =IFERROR(__xludf.DUMMYFUNCTION("XLOOKUP(C10, IMPORTRANGE(""https://docs.google.com/spreadsheets/d/1RJrFMGUC-XijmB6MWr0bUJNzuN7BM1j8R_D0vOt0s8I/edit?usp=sharing"", ""'Master Data TK V0.2 (AUTO)'!F6:F""), IMPORTRANGE(""https://docs.google.com/spreadsheets/d/1RJrFMGUC-XijmB6MWr0bUJNzuN7BM1"&"j8R_D0vOt0s8I/edit?usp=sharing"", ""'Master Data TK V0.2 (AUTO)'!S6:S""))"),"-") -> - | G10: =IFERROR(__xludf.DUMMYFUNCTION("XLOOKUP($C10, IMPORTRANGE(""https://docs.google.com/spreadsheets/d/1RJrFMGUC-XijmB6MWr0bUJNzuN7BM1j8R_D0vOt0s8I/edit?usp=sharing"", ""'Master Data TK V0.2 (AUTO)'!F6:F""), IMPORTRANGE(""https://docs.google.com/spreadsheets/d/1RJrFMGUC-XijmB6MWr0bUJNzuN7BM"&"1j8R_D0vOt0s8I/edit?usp=sharing"", ""'Master Data TK V0.2 (AUTO)'!T6:T""))"),"-") -> - | H10: =IFERROR(__xludf.DUMMYFUNCTION("XLOOKUP($C10, IMPORTRANGE(""https://docs.google.com/spreadsheets/d/1RJrFMGUC-XijmB6MWr0bUJNzuN7BM1j8R_D0vOt0s8I/edit?usp=sharing"", ""'Master Data TK V0.2 (AUTO)'!F6:F""), IMPORTRANGE(""https://docs.google.com/spreadsheets/d/1RJrFMGUC-XijmB6MWr0bUJNzuN7BM"&"1j8R_D0vOt0s8I/edit?usp=sharing"", ""'Master Data TK V0.2 (AUTO)'!V6:V""))"),"") | K10: =IFERROR(__xludf.DUMMYFUNCTION("XLOOKUP($C10, IMPORTRANGE(""https://docs.google.com/spreadsheets/d/1RJrFMGUC-XijmB6MWr0bUJNzuN7BM1j8R_D0vOt0s8I/edit?usp=sharing"", ""'Master Data TK V0.2 (AUTO)'!F6:F""), IMPORTRANGE(""https://docs.google.com/spreadsheets/d/1RJrFMGUC-XijmB6MWr0bUJNzuN7BM"&"1j8R_D0vOt0s8I/edit?usp=sharing"", ""'Master Data TK V0.2 (AUTO)'!W6:W""))"),"") | L10: =IFERROR(__xludf.DUMMYFUNCTION("XLOOKUP($C10, IMPORTRANGE(""https://docs.google.com/spreadsheets/d/1RJrFMGUC-XijmB6MWr0bUJNzuN7BM1j8R_D0vOt0s8I/edit?usp=sharing"", ""'Master Data TK V0.2 (AUTO)'!F6:F""), IMPORTRANGE(""https://docs.google.com/spreadsheets/d/1RJrFMGUC-XijmB6MWr0bUJNzuN7BM"&"1j8R_D0vOt0s8I/edit?usp=sharing"", ""'Master Data TK V0.2 (AUTO)'!X6:X""))"),"")
A11: CRO 1 | B11: Regional Sumut 1 | C11: Koperasi Produsen Maju Bersama | D11: KP-PMB-01 | E11: {=XLOOKUP(C11,'DATA TK PANEN'!D:D,'DATA TK PANEN'!H:H)} -> 786 | F11: =IFERROR(__xludf.DUMMYFUNCTION("XLOOKUP(C11, IMPORTRANGE(""https://docs.google.com/spreadsheets/d/1RJrFMGUC-XijmB6MWr0bUJNzuN7BM1j8R_D0vOt0s8I/edit?usp=sharing"", ""'Master Data TK V0.2 (AUTO)'!F6:F""), IMPORTRANGE(""https://docs.google.com/spreadsheets/d/1RJrFMGUC-XijmB6MWr0bUJNzuN7BM1"&"j8R_D0vOt0s8I/edit?usp=sharing"", ""'Master Data TK V0.2 (AUTO)'!S6:S""))"),16.0) -> 16 | G11: =IFERROR(__xludf.DUMMYFUNCTION("XLOOKUP($C11, IMPORTRANGE(""https://docs.google.com/spreadsheets/d/1RJrFMGUC-XijmB6MWr0bUJNzuN7BM1j8R_D0vOt0s8I/edit?usp=sharing"", ""'Master Data TK V0.2 (AUTO)'!F6:F""), IMPORTRANGE(""https://docs.google.com/spreadsheets/d/1RJrFMGUC-XijmB6MWr0bUJNzuN7BM"&"1j8R_D0vOt0s8I/edit?usp=sharing"", ""'Master Data TK V0.2 (AUTO)'!T6:T""))"),16.0) -> 16 | H11: =IFERROR(__xludf.DUMMYFUNCTION("XLOOKUP($C11, IMPORTRANGE(""https://docs.google.com/spreadsheets/d/1RJrFMGUC-XijmB6MWr0bUJNzuN7BM1j8R_D0vOt0s8I/edit?usp=sharing"", ""'Master Data TK V0.2 (AUTO)'!F6:F""), IMPORTRANGE(""https://docs.google.com/spreadsheets/d/1RJrFMGUC-XijmB6MWr0bUJNzuN7BM"&"1j8R_D0vOt0s8I/edit?usp=sharing"", ""'Master Data TK V0.2 (AUTO)'!V6:V""))"),16.0) -> 16 | K11: =IFERROR(__xludf.DUMMYFUNCTION("XLOOKUP($C11, IMPORTRANGE(""https://docs.google.com/spreadsheets/d/1RJrFMGUC-XijmB6MWr0bUJNzuN7BM1j8R_D0vOt0s8I/edit?usp=sharing"", ""'Master Data TK V0.2 (AUTO)'!F6:F""), IMPORTRANGE(""https://docs.google.com/spreadsheets/d/1RJrFMGUC-XijmB6MWr0bUJNzuN7BM"&"1j8R_D0vOt0s8I/edit?usp=sharing"", ""'Master Data TK V0.2 (AUTO)'!W6:W""))"),0.0) -> 0 | L11: =IFERROR(__xludf.DUMMYFUNCTION("XLOOKUP($C11, IMPORTRANGE(""https://docs.google.com/spreadsheets/d/1RJrFMGUC-XijmB6MWr0bUJNzuN7BM1j8R_D0vOt0s8I/edit?usp=sharing"", ""'Master Data TK V0.2 (AUTO)'!F6:F""), IMPORTRANGE(""https://docs.google.com/spreadsheets/d/1RJrFMGUC-XijmB6MWr0bUJNzuN7BM"&"1j8R_D0vOt0s8I/edit?usp=sharing"", ""'Master Data TK V0.2 (AUTO)'!X6:X""))"),0.0) -> 0
A12: CRO 1 | B12: Regional Sumut 1 | C12: PT Abdi Budi Mulia | D12: PT-ABM-01 | E12: {=XLOOKUP(C12,'DATA TK PANEN'!D:D,'DATA TK PANEN'!H:H)} -> Tidak Ditemukan | F12: =IFERROR(__xludf.DUMMYFUNCTION("XLOOKUP(C12, IMPORTRANGE(""https://docs.google.com/spreadsheets/d/1RJrFMGUC-XijmB6MWr0bUJNzuN7BM1j8R_D0vOt0s8I/edit?usp=sharing"", ""'Master Data TK V0.2 (AUTO)'!F6:F""), IMPORTRANGE(""https://docs.google.com/spreadsheets/d/1RJrFMGUC-XijmB6MWr0bUJNzuN7BM1"&"j8R_D0vOt0s8I/edit?usp=sharing"", ""'Master Data TK V0.2 (AUTO)'!S6:S""))"),"-") -> - | G12: =IFERROR(__xludf.DUMMYFUNCTION("XLOOKUP($C12, IMPORTRANGE(""https://docs.google.com/spreadsheets/d/1RJrFMGUC-XijmB6MWr0bUJNzuN7BM1j8R_D0vOt0s8I/edit?usp=sharing"", ""'Master Data TK V0.2 (AUTO)'!F6:F""), IMPORTRANGE(""https://docs.google.com/spreadsheets/d/1RJrFMGUC-XijmB6MWr0bUJNzuN7BM"&"1j8R_D0vOt0s8I/edit?usp=sharing"", ""'Master Data TK V0.2 (AUTO)'!T6:T""))"),"-") -> - | H12: =IFERROR(__xludf.DUMMYFUNCTION("XLOOKUP($C12, IMPORTRANGE(""https://docs.google.com/spreadsheets/d/1RJrFMGUC-XijmB6MWr0bUJNzuN7BM1j8R_D0vOt0s8I/edit?usp=sharing"", ""'Master Data TK V0.2 (AUTO)'!F6:F""), IMPORTRANGE(""https://docs.google.com/spreadsheets/d/1RJrFMGUC-XijmB6MWr0bUJNzuN7BM"&"1j8R_D0vOt0s8I/edit?usp=sharing"", ""'Master Data TK V0.2 (AUTO)'!V6:V""))"),"") | K12: =IFERROR(__xludf.DUMMYFUNCTION("XLOOKUP($C12, IMPORTRANGE(""https://docs.google.com/spreadsheets/d/1RJrFMGUC-XijmB6MWr0bUJNzuN7BM1j8R_D0vOt0s8I/edit?usp=sharing"", ""'Master Data TK V0.2 (AUTO)'!F6:F""), IMPORTRANGE(""https://docs.google.com/spreadsheets/d/1RJrFMGUC-XijmB6MWr0bUJNzuN7BM"&"1j8R_D0vOt0s8I/edit?usp=sharing"", ""'Master Data TK V0.2 (AUTO)'!W6:W""))"),"") | L12: =IFERROR(__xludf.DUMMYFUNCTION("XLOOKUP($C12, IMPORTRANGE(""https://docs.google.com/spreadsheets/d/1RJrFMGUC-XijmB6MWr0bUJNzuN7BM1j8R_D0vOt0s8I/edit?usp=sharing"", ""'Master Data TK V0.2 (AUTO)'!F6:F""), IMPORTRANGE(""https://docs.google.com/spreadsheets/d/1RJrFMGUC-XijmB6MWr0bUJNzuN7BM"&"1j8R_D0vOt0s8I/edit?usp=sharing"", ""'Master Data TK V0.2 (AUTO)'!X6:X""))"),"")
A13: CRO 1 | B13: Regional Sumut 1 | C13: PT Andalas Intiagro Lestari | D13: PT-AIL-01 | E13: {=XLOOKUP(C13,'DATA TK PANEN'!D:D,'DATA TK PANEN'!H:H)} -> 1.59 | F13: =IFERROR(__xludf.DUMMYFUNCTION("XLOOKUP(C13, IMPORTRANGE(""https://docs.google.com/spreadsheets/d/1RJrFMGUC-XijmB6MWr0bUJNzuN7BM1j8R_D0vOt0s8I/edit?usp=sharing"", ""'Master Data TK V0.2 (AUTO)'!F6:F""), IMPORTRANGE(""https://docs.google.com/spreadsheets/d/1RJrFMGUC-XijmB6MWr0bUJNzuN7BM1"&"j8R_D0vOt0s8I/edit?usp=sharing"", ""'Master Data TK V0.2 (AUTO)'!S6:S""))"),1.0) -> 1 | G13: =IFERROR(__xludf.DUMMYFUNCTION("XLOOKUP($C13, IMPORTRANGE(""https://docs.google.com/spreadsheets/d/1RJrFMGUC-XijmB6MWr0bUJNzuN7BM1j8R_D0vOt0s8I/edit?usp=sharing"", ""'Master Data TK V0.2 (AUTO)'!F6:F""), IMPORTRANGE(""https://docs.google.com/spreadsheets/d/1RJrFMGUC-XijmB6MWr0bUJNzuN7BM"&"1j8R_D0vOt0s8I/edit?usp=sharing"", ""'Master Data TK V0.2 (AUTO)'!T6:T""))"),1.0) -> 1 | H13: =IFERROR(__xludf.DUMMYFUNCTION("XLOOKUP($C13, IMPORTRANGE(""https://docs.google.com/spreadsheets/d/1RJrFMGUC-XijmB6MWr0bUJNzuN7BM1j8R_D0vOt0s8I/edit?usp=sharing"", ""'Master Data TK V0.2 (AUTO)'!F6:F""), IMPORTRANGE(""https://docs.google.com/spreadsheets/d/1RJrFMGUC-XijmB6MWr0bUJNzuN7BM"&"1j8R_D0vOt0s8I/edit?usp=sharing"", ""'Master Data TK V0.2 (AUTO)'!V6:V""))"),"") | K13: =IFERROR(__xludf.DUMMYFUNCTION("XLOOKUP($C13, IMPORTRANGE(""https://docs.google.com/spreadsheets/d/1RJrFMGUC-XijmB6MWr0bUJNzuN7BM1j8R_D0vOt0s8I/edit?usp=sharing"", ""'Master Data TK V0.2 (AUTO)'!F6:F""), IMPORTRANGE(""https://docs.google.com/spreadsheets/d/1RJrFMGUC-XijmB6MWr0bUJNzuN7BM"&"1j8R_D0vOt0s8I/edit?usp=sharing"", ""'Master Data TK V0.2 (AUTO)'!W6:W""))"),"") | L13: =IFERROR(__xludf.DUMMYFUNCTION("XLOOKUP($C13, IMPORTRANGE(""https://docs.google.com/spreadsheets/d/1RJrFMGUC-XijmB6MWr0bUJNzuN7BM1j8R_D0vOt0s8I/edit?usp=sharing"", ""'Master Data TK V0.2 (AUTO)'!F6:F""), IMPORTRANGE(""https://docs.google.com/spreadsheets/d/1RJrFMGUC-XijmB6MWr0bUJNzuN7BM"&"1j8R_D0vOt0s8I/edit?usp=sharing"", ""'Master Data TK V0.2 (AUTO)'!X6:X""))"),"")
A14: CRO 1 | B14: Regional Sumut 1 | C14: PT Anugerah Langkat Makmur | D14: PT-ALM-01 | E14: {=XLOOKUP(C14,'DATA TK PANEN'!D:D,'DATA TK PANEN'!H:H)} -> 0 | F14: =IFERROR(__xludf.DUMMYFUNCTION("XLOOKUP(C14, IMPORTRANGE(""https://docs.google.com/spreadsheets/d/1RJrFMGUC-XijmB6MWr0bUJNzuN7BM1j8R_D0vOt0s8I/edit?usp=sharing"", ""'Master Data TK V0.2 (AUTO)'!F6:F""), IMPORTRANGE(""https://docs.google.com/spreadsheets/d/1RJrFMGUC-XijmB6MWr0bUJNzuN7BM1"&"j8R_D0vOt0s8I/edit?usp=sharing"", ""'Master Data TK V0.2 (AUTO)'!S6:S""))"),"-") -> - | G14: =IFERROR(__xludf.DUMMYFUNCTION("XLOOKUP($C14, IMPORTRANGE(""https://docs.google.com/spreadsheets/d/1RJrFMGUC-XijmB6MWr0bUJNzuN7BM1j8R_D0vOt0s8I/edit?usp=sharing"", ""'Master Data TK V0.2 (AUTO)'!F6:F""), IMPORTRANGE(""https://docs.google.com/spreadsheets/d/1RJrFMGUC-XijmB6MWr0bUJNzuN7BM"&"1j8R_D0vOt0s8I/edit?usp=sharing"", ""'Master Data TK V0.2 (AUTO)'!T6:T""))"),"-") -> - | H14: =IFERROR(__xludf.DUMMYFUNCTION("XLOOKUP($C14, IMPORTRANGE(""https://docs.google.com/spreadsheets/d/1RJrFMGUC-XijmB6MWr0bUJNzuN7BM1j8R_D0vOt0s8I/edit?usp=sharing"", ""'Master Data TK V0.2 (AUTO)'!F6:F""), IMPORTRANGE(""https://docs.google.com/spreadsheets/d/1RJrFMGUC-XijmB6MWr0bUJNzuN7BM"&"1j8R_D0vOt0s8I/edit?usp=sharing"", ""'Master Data TK V0.2 (AUTO)'!V6:V""))"),"") | K14: =IFERROR(__xludf.DUMMYFUNCTION("XLOOKUP($C14, IMPORTRANGE(""https://docs.google.com/spreadsheets/d/1RJrFMGUC-XijmB6MWr0bUJNzuN7BM1j8R_D0vOt0s8I/edit?usp=sharing"", ""'Master Data TK V0.2 (AUTO)'!F6:F""), IMPORTRANGE(""https://docs.google.com/spreadsheets/d/1RJrFMGUC-XijmB6MWr0bUJNzuN7BM"&"1j8R_D0vOt0s8I/edit?usp=sharing"", ""'Master Data TK V0.2 (AUTO)'!W6:W""))"),"") | L14: =IFERROR(__xludf.DUMMYFUNCTION("XLOOKUP($C14, IMPORTRANGE(""https://docs.google.com/spreadsheets/d/1RJrFMGUC-XijmB6MWr0bUJNzuN7BM1j8R_D0vOt0s8I/edit?usp=sharing"", ""'Master Data TK V0.2 (AUTO)'!F6:F""), IMPORTRANGE(""https://docs.google.com/spreadsheets/d/1RJrFMGUC-XijmB6MWr0bUJNzuN7BM"&"1j8R_D0vOt0s8I/edit?usp=sharing"", ""'Master Data TK V0.2 (AUTO)'!X6:X""))"),"")
A15: CRO 1 | B15: Regional Sumut 1 | C15: PT Anugerah Sawindo | D15: PT-ASN-01 | E15: {=XLOOKUP(C15,'DATA TK PANEN'!D:D,'DATA TK PANEN'!H:H)} -> 44.46 | F15: =IFERROR(__xludf.DUMMYFUNCTION("XLOOKUP(C15, IMPORTRANGE(""https://docs.google.com/spreadsheets/d/1RJrFMGUC-XijmB6MWr0bUJNzuN7BM1j8R_D0vOt0s8I/edit?usp=sharing"", ""'Master Data TK V0.2 (AUTO)'!F6:F""), IMPORTRANGE(""https://docs.google.com/spreadsheets/d/1RJrFMGUC-XijmB6MWr0bUJNzuN7BM1"&"j8R_D0vOt0s8I/edit?usp=sharing"", ""'Master Data TK V0.2 (AUTO)'!S6:S""))"),3.0) -> 3 | G15: =IFERROR(__xludf.DUMMYFUNCTION("XLOOKUP($C15, IMPORTRANGE(""https://docs.google.com/spreadsheets/d/1RJrFMGUC-XijmB6MWr0bUJNzuN7BM1j8R_D0vOt0s8I/edit?usp=sharing"", ""'Master Data TK V0.2 (AUTO)'!F6:F""), IMPORTRANGE(""https://docs.google.com/spreadsheets/d/1RJrFMGUC-XijmB6MWr0bUJNzuN7BM"&"1j8R_D0vOt0s8I/edit?usp=sharing"", ""'Master Data TK V0.2 (AUTO)'!T6:T""))"),"-") -> - | H15: =IFERROR(__xludf.DUMMYFUNCTION("XLOOKUP($C15, IMPORTRANGE(""https://docs.google.com/spreadsheets/d/1RJrFMGUC-XijmB6MWr0bUJNzuN7BM1j8R_D0vOt0s8I/edit?usp=sharing"", ""'Master Data TK V0.2 (AUTO)'!F6:F""), IMPORTRANGE(""https://docs.google.com/spreadsheets/d/1RJrFMGUC-XijmB6MWr0bUJNzuN7BM"&"1j8R_D0vOt0s8I/edit?usp=sharing"", ""'Master Data TK V0.2 (AUTO)'!V6:V""))"),"") | K15: =IFERROR(__xludf.DUMMYFUNCTION("XLOOKUP($C15, IMPORTRANGE(""https://docs.google.com/spreadsheets/d/1RJrFMGUC-XijmB6MWr0bUJNzuN7BM1j8R_D0vOt0s8I/edit?usp=sharing"", ""'Master Data TK V0.2 (AUTO)'!F6:F""), IMPORTRANGE(""https://docs.google.com/spreadsheets/d/1RJrFMGUC-XijmB6MWr0bUJNzuN7BM"&"1j8R_D0vOt0s8I/edit?usp=sharing"", ""'Master Data TK V0.2 (AUTO)'!W6:W""))"),"") | L15: =IFERROR(__xludf.DUMMYFUNCTION("XLOOKUP($C15, IMPORTRANGE(""https://docs.google.com/spreadsheets/d/1RJrFMGUC-XijmB6MWr0bUJNzuN7BM1j8R_D0vOt0s8I/edit?usp=sharing"", ""'Master Data TK V0.2 (AUTO)'!F6:F""), IMPORTRANGE(""https://docs.google.com/spreadsheets/d/1RJrFMGUC-XijmB6MWr0bUJNzuN7BM"&"1j8R_D0vOt0s8I/edit?usp=sharing"", ""'Master Data TK V0.2 (AUTO)'!X6:X""))"),"")
A16: CRO 1 | B16: Regional Sumut 1 | C16: PT Austindo Nusantara Jaya Agri | D16: PT-ANJ-01 | E16: {=XLOOKUP(C16,'DATA TK PANEN'!D:D,'DATA TK PANEN'!H:H)} -> Tidak Ditemukan | F16: =IFERROR(__xludf.DUMMYFUNCTION("XLOOKUP(C16, IMPORTRANGE(""https://docs.google.com/spreadsheets/d/1RJrFMGUC-XijmB6MWr0bUJNzuN7BM1j8R_D0vOt0s8I/edit?usp=sharing"", ""'Master Data TK V0.2 (AUTO)'!F6:F""), IMPORTRANGE(""https://docs.google.com/spreadsheets/d/1RJrFMGUC-XijmB6MWr0bUJNzuN7BM1"&"j8R_D0vOt0s8I/edit?usp=sharing"", ""'Master Data TK V0.2 (AUTO)'!S6:S""))"),"-") -> - | G16: =IFERROR(__xludf.DUMMYFUNCTION("XLOOKUP($C16, IMPORTRANGE(""https://docs.google.com/spreadsheets/d/1RJrFMGUC-XijmB6MWr0bUJNzuN7BM1j8R_D0vOt0s8I/edit?usp=sharing"", ""'Master Data TK V0.2 (AUTO)'!F6:F""), IMPORTRANGE(""https://docs.google.com/spreadsheets/d/1RJrFMGUC-XijmB6MWr0bUJNzuN7BM"&"1j8R_D0vOt0s8I/edit?usp=sharing"", ""'Master Data TK V0.2 (AUTO)'!T6:T""))"),"-") -> - | H16: =IFERROR(__xludf.DUMMYFUNCTION("XLOOKUP($C16, IMPORTRANGE(""https://docs.google.com/spreadsheets/d/1RJrFMGUC-XijmB6MWr0bUJNzuN7BM1j8R_D0vOt0s8I/edit?usp=sharing"", ""'Master Data TK V0.2 (AUTO)'!F6:F""), IMPORTRANGE(""https://docs.google.com/spreadsheets/d/1RJrFMGUC-XijmB6MWr0bUJNzuN7BM"&"1j8R_D0vOt0s8I/edit?usp=sharing"", ""'Master Data TK V0.2 (AUTO)'!V6:V""))"),"") | K16: =IFERROR(__xludf.DUMMYFUNCTION("XLOOKUP($C16, IMPORTRANGE(""https://docs.google.com/spreadsheets/d/1RJrFMGUC-XijmB6MWr0bUJNzuN7BM1j8R_D0vOt0s8I/edit?usp=sharing"", ""'Master Data TK V0.2 (AUTO)'!F6:F""), IMPORTRANGE(""https://docs.google.com/spreadsheets/d/1RJrFMGUC-XijmB6MWr0bUJNzuN7BM"&"1j8R_D0vOt0s8I/edit?usp=sharing"", ""'Master Data TK V0.2 (AUTO)'!W6:W""))"),"") | L16: =IFERROR(__xludf.DUMMYFUNCTION("XLOOKUP($C16, IMPORTRANGE(""https://docs.google.com/spreadsheets/d/1RJrFMGUC-XijmB6MWr0bUJNzuN7BM1j8R_D0vOt0s8I/edit?usp=sharing"", ""'Master Data TK V0.2 (AUTO)'!F6:F""), IMPORTRANGE(""https://docs.google.com/spreadsheets/d/1RJrFMGUC-XijmB6MWr0bUJNzuN7BM"&"1j8R_D0vOt0s8I/edit?usp=sharing"", ""'Master Data TK V0.2 (AUTO)'!X6:X""))"),"")
A17: CRO 1 | B17: Regional Sumut 1 | C17: PT Bakrie Sumatera Plantations/Bakrie Group | D17: PT-BSP-01 | E17: {=XLOOKUP(C17,'DATA TK PANEN'!D:D,'DATA TK PANEN'!H:H)} -> 0 | F17: =IFERROR(__xludf.DUMMYFUNCTION("XLOOKUP(C17, IMPORTRANGE(""https://docs.google.com/spreadsheets/d/1RJrFMGUC-XijmB6MWr0bUJNzuN7BM1j8R_D0vOt0s8I/edit?usp=sharing"", ""'Master Data TK V0.2 (AUTO)'!F6:F""), IMPORTRANGE(""https://docs.google.com/spreadsheets/d/1RJrFMGUC-XijmB6MWr0bUJNzuN7BM1"&"j8R_D0vOt0s8I/edit?usp=sharing"", ""'Master Data TK V0.2 (AUTO)'!S6:S""))"),"-") -> - | G17: =IFERROR(__xludf.DUMMYFUNCTION("XLOOKUP($C17, IMPORTRANGE(""https://docs.google.com/spreadsheets/d/1RJrFMGUC-XijmB6MWr0bUJNzuN7BM1j8R_D0vOt0s8I/edit?usp=sharing"", ""'Master Data TK V0.2 (AUTO)'!F6:F""), IMPORTRANGE(""https://docs.google.com/spreadsheets/d/1RJrFMGUC-XijmB6MWr0bUJNzuN7BM"&"1j8R_D0vOt0s8I/edit?usp=sharing"", ""'Master Data TK V0.2 (AUTO)'!T6:T""))"),"-") -> - | H17: =IFERROR(__xludf.DUMMYFUNCTION("XLOOKUP($C17, IMPORTRANGE(""https://docs.google.com/spreadsheets/d/1RJrFMGUC-XijmB6MWr0bUJNzuN7BM1j8R_D0vOt0s8I/edit?usp=sharing"", ""'Master Data TK V0.2 (AUTO)'!F6:F""), IMPORTRANGE(""https://docs.google.com/spreadsheets/d/1RJrFMGUC-XijmB6MWr0bUJNzuN7BM"&"1j8R_D0vOt0s8I/edit?usp=sharing"", ""'Master Data TK V0.2 (AUTO)'!V6:V""))"),"") | K17: =IFERROR(__xludf.DUMMYFUNCTION("XLOOKUP($C17, IMPORTRANGE(""https://docs.google.com/spreadsheets/d/1RJrFMGUC-XijmB6MWr0bUJNzuN7BM1j8R_D0vOt0s8I/edit?usp=sharing"", ""'Master Data TK V0.2 (AUTO)'!F6:F""), IMPORTRANGE(""https://docs.google.com/spreadsheets/d/1RJrFMGUC-XijmB6MWr0bUJNzuN7BM"&"1j8R_D0vOt0s8I/edit?usp=sharing"", ""'Master Data TK V0.2 (AUTO)'!W6:W""))"),"") | L17: =IFERROR(__xludf.DUMMYFUNCTION("XLOOKUP($C17, IMPORTRANGE(""https://docs.google.com/spreadsheets/d/1RJrFMGUC-XijmB6MWr0bUJNzuN7BM1j8R_D0vOt0s8I/edit?usp=sharing"", ""'Master Data TK V0.2 (AUTO)'!F6:F""), IMPORTRANGE(""https://docs.google.com/spreadsheets/d/1RJrFMGUC-XijmB6MWr0bUJNzuN7BM"&"1j8R_D0vOt0s8I/edit?usp=sharing"", ""'Master Data TK V0.2 (AUTO)'!X6:X""))"),"")
A18: CRO 1 | B18: Regional Sumut 1 | C18: PT Bandar Meriah* | D18: PT-BMA-01 | E18: {=XLOOKUP(C18,'DATA TK PANEN'!D:D,'DATA TK PANEN'!H:H)} -> 0 | F18: =IFERROR(__xludf.DUMMYFUNCTION("XLOOKUP(C18, IMPORTRANGE(""https://docs.google.com/spreadsheets/d/1RJrFMGUC-XijmB6MWr0bUJNzuN7BM1j8R_D0vOt0s8I/edit?usp=sharing"", ""'Master Data TK V0.2 (AUTO)'!F6:F""), IMPORTRANGE(""https://docs.google.com/spreadsheets/d/1RJrFMGUC-XijmB6MWr0bUJNzuN7BM1"&"j8R_D0vOt0s8I/edit?usp=sharing"", ""'Master Data TK V0.2 (AUTO)'!S6:S""))"),"-") -> - | G18: =IFERROR(__xludf.DUMMYFUNCTION("XLOOKUP($C18, IMPORTRANGE(""https://docs.google.com/spreadsheets/d/1RJrFMGUC-XijmB6MWr0bUJNzuN7BM1j8R_D0vOt0s8I/edit?usp=sharing"", ""'Master Data TK V0.2 (AUTO)'!F6:F""), IMPORTRANGE(""https://docs.google.com/spreadsheets/d/1RJrFMGUC-XijmB6MWr0bUJNzuN7BM"&"1j8R_D0vOt0s8I/edit?usp=sharing"", ""'Master Data TK V0.2 (AUTO)'!T6:T""))"),"-") -> - | H18: =IFERROR(__xludf.DUMMYFUNCTION("XLOOKUP($C18, IMPORTRANGE(""https://docs.google.com/spreadsheets/d/1RJrFMGUC-XijmB6MWr0bUJNzuN7BM1j8R_D0vOt0s8I/edit?usp=sharing"", ""'Master Data TK V0.2 (AUTO)'!F6:F""), IMPORTRANGE(""https://docs.google.com/spreadsheets/d/1RJrFMGUC-XijmB6MWr0bUJNzuN7BM"&"1j8R_D0vOt0s8I/edit?usp=sharing"", ""'Master Data TK V0.2 (AUTO)'!V6:V""))"),"") | K18: =IFERROR(__xludf.DUMMYFUNCTION("XLOOKUP($C18, IMPORTRANGE(""https://docs.google.com/spreadsheets/d/1RJrFMGUC-XijmB6MWr0bUJNzuN7BM1j8R_D0vOt0s8I/edit?usp=sharing"", ""'Master Data TK V0.2 (AUTO)'!F6:F""), IMPORTRANGE(""https://docs.google.com/spreadsheets/d/1RJrFMGUC-XijmB6MWr0bUJNzuN7BM"&"1j8R_D0vOt0s8I/edit?usp=sharing"", ""'Master Data TK V0.2 (AUTO)'!W6:W""))"),"") | L18: =IFERROR(__xludf.DUMMYFUNCTION("XLOOKUP($C18, IMPORTRANGE(""https://docs.google.com/spreadsheets/d/1RJrFMGUC-XijmB6MWr0bUJNzuN7BM1j8R_D0vOt0s8I/edit?usp=sharing"", ""'Master Data TK V0.2 (AUTO)'!F6:F""), IMPORTRANGE(""https://docs.google.com/spreadsheets/d/1RJrFMGUC-XijmB6MWr0bUJNzuN7BM"&"1j8R_D0vOt0s8I/edit?usp=sharing"", ""'Master Data TK V0.2 (AUTO)'!X6:X""))"),"")
A19: CRO 1 | B19: Regional Sumut 1 | C19: PT Barumun Raya Padang Langkat | D19: PT-BRP-01 | E19: {=XLOOKUP(C19,'DATA TK PANEN'!D:D,'DATA TK PANEN'!H:H)} -> 0 | F19: =IFERROR(__xludf.DUMMYFUNCTION("XLOOKUP(C19, IMPORTRANGE(""https://docs.google.com/spreadsheets/d/1RJrFMGUC-XijmB6MWr0bUJNzuN7BM1j8R_D0vOt0s8I/edit?usp=sharing"", ""'Master Data TK V0.2 (AUTO)'!F6:F""), IMPORTRANGE(""https://docs.google.com/spreadsheets/d/1RJrFMGUC-XijmB6MWr0bUJNzuN7BM1"&"j8R_D0vOt0s8I/edit?usp=sharing"", ""'Master Data TK V0.2 (AUTO)'!S6:S""))"),"-") -> - | G19: =IFERROR(__xludf.DUMMYFUNCTION("XLOOKUP($C19, IMPORTRANGE(""https://docs.google.com/spreadsheets/d/1RJrFMGUC-XijmB6MWr0bUJNzuN7BM1j8R_D0vOt0s8I/edit?usp=sharing"", ""'Master Data TK V0.2 (AUTO)'!F6:F""), IMPORTRANGE(""https://docs.google.com/spreadsheets/d/1RJrFMGUC-XijmB6MWr0bUJNzuN7BM"&"1j8R_D0vOt0s8I/edit?usp=sharing"", ""'Master Data TK V0.2 (AUTO)'!T6:T""))"),"-") -> - | H19: =IFERROR(__xludf.DUMMYFUNCTION("XLOOKUP($C19, IMPORTRANGE(""https://docs.google.com/spreadsheets/d/1RJrFMGUC-XijmB6MWr0bUJNzuN7BM1j8R_D0vOt0s8I/edit?usp=sharing"", ""'Master Data TK V0.2 (AUTO)'!F6:F""), IMPORTRANGE(""https://docs.google.com/spreadsheets/d/1RJrFMGUC-XijmB6MWr0bUJNzuN7BM"&"1j8R_D0vOt0s8I/edit?usp=sharing"", ""'Master Data TK V0.2 (AUTO)'!V6:V""))"),"") | K19: =IFERROR(__xludf.DUMMYFUNCTION("XLOOKUP($C19, IMPORTRANGE(""https://docs.google.com/spreadsheets/d/1RJrFMGUC-XijmB6MWr0bUJNzuN7BM1j8R_D0vOt0s8I/edit?usp=sharing"", ""'Master Data TK V0.2 (AUTO)'!F6:F""), IMPORTRANGE(""https://docs.google.com/spreadsheets/d/1RJrFMGUC-XijmB6MWr0bUJNzuN7BM"&"1j8R_D0vOt0s8I/edit?usp=sharing"", ""'Master Data TK V0.2 (AUTO)'!W6:W""))"),"") | L19: =IFERROR(__xludf.DUMMYFUNCTION("XLOOKUP($C19, IMPORTRANGE(""https://docs.google.com/spreadsheets/d/1RJrFMGUC-XijmB6MWr0bUJNzuN7BM1j8R_D0vOt0s8I/edit?usp=sharing"", ""'Master Data TK V0.2 (AUTO)'!F6:F""), IMPORTRANGE(""https://docs.google.com/spreadsheets/d/1RJrFMGUC-XijmB6MWr0bUJNzuN7BM"&"1j8R_D0vOt0s8I/edit?usp=sharing"", ""'Master Data TK V0.2 (AUTO)'!X6:X""))"),"")
A20: CRO 1 | B20: Regional Sumut 1 | C20: PT Gaharu Mas | D20: PT-GMA-01 | E20: {=XLOOKUP(C20,'DATA TK PANEN'!D:D,'DATA TK PANEN'!H:H)} -> Tidak Ditemukan | F20: =IFERROR(__xludf.DUMMYFUNCTION("XLOOKUP(C20, IMPORTRANGE(""https://docs.google.com/spreadsheets/d/1RJrFMGUC-XijmB6MWr0bUJNzuN7BM1j8R_D0vOt0s8I/edit?usp=sharing"", ""'Master Data TK V0.2 (AUTO)'!F6:F""), IMPORTRANGE(""https://docs.google.com/spreadsheets/d/1RJrFMGUC-XijmB6MWr0bUJNzuN7BM1"&"j8R_D0vOt0s8I/edit?usp=sharing"", ""'Master Data TK V0.2 (AUTO)'!S6:S""))"),"-") -> - | G20: =IFERROR(__xludf.DUMMYFUNCTION("XLOOKUP($C20, IMPORTRANGE(""https://docs.google.com/spreadsheets/d/1RJrFMGUC-XijmB6MWr0bUJNzuN7BM1j8R_D0vOt0s8I/edit?usp=sharing"", ""'Master Data TK V0.2 (AUTO)'!F6:F""), IMPORTRANGE(""https://docs.google.com/spreadsheets/d/1RJrFMGUC-XijmB6MWr0bUJNzuN7BM"&"1j8R_D0vOt0s8I/edit?usp=sharing"", ""'Master Data TK V0.2 (AUTO)'!T6:T""))"),"-") -> - | H20: =IFERROR(__xludf.DUMMYFUNCTION("XLOOKUP($C20, IMPORTRANGE(""https://docs.google.com/spreadsheets/d/1RJrFMGUC-XijmB6MWr0bUJNzuN7BM1j8R_D0vOt0s8I/edit?usp=sharing"", ""'Master Data TK V0.2 (AUTO)'!F6:F""), IMPORTRANGE(""https://docs.google.com/spreadsheets/d/1RJrFMGUC-XijmB6MWr0bUJNzuN7BM"&"1j8R_D0vOt0s8I/edit?usp=sharing"", ""'Master Data TK V0.2 (AUTO)'!V6:V""))"),"") | K20: =IFERROR(__xludf.DUMMYFUNCTION("XLOOKUP($C20, IMPORTRANGE(""https://docs.google.com/spreadsheets/d/1RJrFMGUC-XijmB6MWr0bUJNzuN7BM1j8R_D0vOt0s8I/edit?usp=sharing"", ""'Master Data TK V0.2 (AUTO)'!F6:F""), IMPORTRANGE(""https://docs.google.com/spreadsheets/d/1RJrFMGUC-XijmB6MWr0bUJNzuN7BM"&"1j8R_D0vOt0s8I/edit?usp=sharing"", ""'Master Data TK V0.2 (AUTO)'!W6:W""))"),"") | L20: =IFERROR(__xludf.DUMMYFUNCTION("XLOOKUP($C20, IMPORTRANGE(""https://docs.google.com/spreadsheets/d/1RJrFMGUC-XijmB6MWr0bUJNzuN7BM1j8R_D0vOt0s8I/edit?usp=sharing"", ""'Master Data TK V0.2 (AUTO)'!F6:F""), IMPORTRANGE(""https://docs.google.com/spreadsheets/d/1RJrFMGUC-XijmB6MWr0bUJNzuN7BM"&"1j8R_D0vOt0s8I/edit?usp=sharing"", ""'Master Data TK V0.2 (AUTO)'!X6:X""))"),"")
A21: CRO 1 | B21: Regional Sumut 1 | C21: PT Agrinas Palma Nusantara | D21: PT-APN-02 | E21: {=XLOOKUP(C21,'DATA TK PANEN'!D:D,'DATA TK PANEN'!H:H)} -> 3260.34 | F21: =IFERROR(__xludf.DUMMYFUNCTION("XLOOKUP(C21, IMPORTRANGE(""https://docs.google.com/spreadsheets/d/1RJrFMGUC-XijmB6MWr0bUJNzuN7BM1j8R_D0vOt0s8I/edit?usp=sharing"", ""'Master Data TK V0.2 (AUTO)'!F6:F""), IMPORTRANGE(""https://docs.google.com/spreadsheets/d/1RJrFMGUC-XijmB6MWr0bUJNzuN7BM1"&"j8R_D0vOt0s8I/edit?usp=sharing"", ""'Master Data TK V0.2 (AUTO)'!S6:S""))"),196.0) -> 196 | G21: =IFERROR(__xludf.DUMMYFUNCTION("XLOOKUP($C21, IMPORTRANGE(""https://docs.google.com/spreadsheets/d/1RJrFMGUC-XijmB6MWr0bUJNzuN7BM1j8R_D0vOt0s8I/edit?usp=sharing"", ""'Master Data TK V0.2 (AUTO)'!F6:F""), IMPORTRANGE(""https://docs.google.com/spreadsheets/d/1RJrFMGUC-XijmB6MWr0bUJNzuN7BM"&"1j8R_D0vOt0s8I/edit?usp=sharing"", ""'Master Data TK V0.2 (AUTO)'!T6:T""))"),135.0) -> 135 | H21: =IFERROR(__xludf.DUMMYFUNCTION("XLOOKUP($C21, IMPORTRANGE(""https://docs.google.com/spreadsheets/d/1RJrFMGUC-XijmB6MWr0bUJNzuN7BM1j8R_D0vOt0s8I/edit?usp=sharing"", ""'Master Data TK V0.2 (AUTO)'!F6:F""), IMPORTRANGE(""https://docs.google.com/spreadsheets/d/1RJrFMGUC-XijmB6MWr0bUJNzuN7BM"&"1j8R_D0vOt0s8I/edit?usp=sharing"", ""'Master Data TK V0.2 (AUTO)'!V6:V""))"),149.0) -> 149 | K21: =IFERROR(__xludf.DUMMYFUNCTION("XLOOKUP($C21, IMPORTRANGE(""https://docs.google.com/spreadsheets/d/1RJrFMGUC-XijmB6MWr0bUJNzuN7BM1j8R_D0vOt0s8I/edit?usp=sharing"", ""'Master Data TK V0.2 (AUTO)'!F6:F""), IMPORTRANGE(""https://docs.google.com/spreadsheets/d/1RJrFMGUC-XijmB6MWr0bUJNzuN7BM"&"1j8R_D0vOt0s8I/edit?usp=sharing"", ""'Master Data TK V0.2 (AUTO)'!W6:W""))"),20.0) -> 20 | L21: =IFERROR(__xludf.DUMMYFUNCTION("XLOOKUP($C21, IMPORTRANGE(""https://docs.google.com/spreadsheets/d/1RJrFMGUC-XijmB6MWr0bUJNzuN7BM1j8R_D0vOt0s8I/edit?usp=sharing"", ""'Master Data TK V0.2 (AUTO)'!F6:F""), IMPORTRANGE(""https://docs.google.com/spreadsheets/d/1RJrFMGUC-XijmB6MWr0bUJNzuN7BM"&"1j8R_D0vOt0s8I/edit?usp=sharing"", ""'Master Data TK V0.2 (AUTO)'!X6:X""))"),27.0) -> 27
A22: CRO 1 | B22: Regional Sumut 1 | C22: PT Gunung Bangau | D22: PT-GBU-01 | E22: {=XLOOKUP(C22,'DATA TK PANEN'!D:D,'DATA TK PANEN'!H:H)} -> 0 | F22: =IFERROR(__xludf.DUMMYFUNCTION("XLOOKUP(C22, IMPORTRANGE(""https://docs.google.com/spreadsheets/d/1RJrFMGUC-XijmB6MWr0bUJNzuN7BM1j8R_D0vOt0s8I/edit?usp=sharing"", ""'Master Data TK V0.2 (AUTO)'!F6:F""), IMPORTRANGE(""https://docs.google.com/spreadsheets/d/1RJrFMGUC-XijmB6MWr0bUJNzuN7BM1"&"j8R_D0vOt0s8I/edit?usp=sharing"", ""'Master Data TK V0.2 (AUTO)'!S6:S""))"),"-") -> - | G22: =IFERROR(__xludf.DUMMYFUNCTION("XLOOKUP($C22, IMPORTRANGE(""https://docs.google.com/spreadsheets/d/1RJrFMGUC-XijmB6MWr0bUJNzuN7BM1j8R_D0vOt0s8I/edit?usp=sharing"", ""'Master Data TK V0.2 (AUTO)'!F6:F""), IMPORTRANGE(""https://docs.google.com/spreadsheets/d/1RJrFMGUC-XijmB6MWr0bUJNzuN7BM"&"1j8R_D0vOt0s8I/edit?usp=sharing"", ""'Master Data TK V0.2 (AUTO)'!T6:T""))"),"-") -> - | H22: =IFERROR(__xludf.DUMMYFUNCTION("XLOOKUP($C22, IMPORTRANGE(""https://docs.google.com/spreadsheets/d/1RJrFMGUC-XijmB6MWr0bUJNzuN7BM1j8R_D0vOt0s8I/edit?usp=sharing"", ""'Master Data TK V0.2 (AUTO)'!F6:F""), IMPORTRANGE(""https://docs.google.com/spreadsheets/d/1RJrFMGUC-XijmB6MWr0bUJNzuN7BM"&"1j8R_D0vOt0s8I/edit?usp=sharing"", ""'Master Data TK V0.2 (AUTO)'!V6:V""))"),"") | K22: =IFERROR(__xludf.DUMMYFUNCTION("XLOOKUP($C22, IMPORTRANGE(""https://docs.google.com/spreadsheets/d/1RJrFMGUC-XijmB6MWr0bUJNzuN7BM1j8R_D0vOt0s8I/edit?usp=sharing"", ""'Master Data TK V0.2 (AUTO)'!F6:F""), IMPORTRANGE(""https://docs.google.com/spreadsheets/d/1RJrFMGUC-XijmB6MWr0bUJNzuN7BM"&"1j8R_D0vOt0s8I/edit?usp=sharing"", ""'Master Data TK V0.2 (AUTO)'!W6:W""))"),"") | L22: =IFERROR(__xludf.DUMMYFUNCTION("XLOOKUP($C22, IMPORTRANGE(""https://docs.google.com/spreadsheets/d/1RJrFMGUC-XijmB6MWr0bUJNzuN7BM1j8R_D0vOt0s8I/edit?usp=sharing"", ""'Master Data TK V0.2 (AUTO)'!F6:F""), IMPORTRANGE(""https://docs.google.com/spreadsheets/d/1RJrFMGUC-XijmB6MWr0bUJNzuN7BM"&"1j8R_D0vOt0s8I/edit?usp=sharing"", ""'Master Data TK V0.2 (AUTO)'!X6:X""))"),"")
A23: CRO 1 | B23: Regional Sumut 1 | C23: PT Hexansetia Sawita | D23: PT-HSE-01 | E23: {=XLOOKUP(C23,'DATA TK PANEN'!D:D,'DATA TK PANEN'!H:H)} -> Tidak Ditemukan | F23: =IFERROR(__xludf.DUMMYFUNCTION("XLOOKUP(C23, IMPORTRANGE(""https://docs.google.com/spreadsheets/d/1RJrFMGUC-XijmB6MWr0bUJNzuN7BM1j8R_D0vOt0s8I/edit?usp=sharing"", ""'Master Data TK V0.2 (AUTO)'!F6:F""), IMPORTRANGE(""https://docs.google.com/spreadsheets/d/1RJrFMGUC-XijmB6MWr0bUJNzuN7BM1"&"j8R_D0vOt0s8I/edit?usp=sharing"", ""'Master Data TK V0.2 (AUTO)'!S6:S""))"),"-") -> - | G23: =IFERROR(__xludf.DUMMYFUNCTION("XLOOKUP($C23, IMPORTRANGE(""https://docs.google.com/spreadsheets/d/1RJrFMGUC-XijmB6MWr0bUJNzuN7BM1j8R_D0vOt0s8I/edit?usp=sharing"", ""'Master Data TK V0.2 (AUTO)'!F6:F""), IMPORTRANGE(""https://docs.google.com/spreadsheets/d/1RJrFMGUC-XijmB6MWr0bUJNzuN7BM"&"1j8R_D0vOt0s8I/edit?usp=sharing"", ""'Master Data TK V0.2 (AUTO)'!T6:T""))"),"-") -> - | H23: =IFERROR(__xludf.DUMMYFUNCTION("XLOOKUP($C23, IMPORTRANGE(""https://docs.google.com/spreadsheets/d/1RJrFMGUC-XijmB6MWr0bUJNzuN7BM1j8R_D0vOt0s8I/edit?usp=sharing"", ""'Master Data TK V0.2 (AUTO)'!F6:F""), IMPORTRANGE(""https://docs.google.com/spreadsheets/d/1RJrFMGUC-XijmB6MWr0bUJNzuN7BM"&"1j8R_D0vOt0s8I/edit?usp=sharing"", ""'Master Data TK V0.2 (AUTO)'!V6:V""))"),"") | K23: =IFERROR(__xludf.DUMMYFUNCTION("XLOOKUP($C23, IMPORTRANGE(""https://docs.google.com/spreadsheets/d/1RJrFMGUC-XijmB6MWr0bUJNzuN7BM1j8R_D0vOt0s8I/edit?usp=sharing"", ""'Master Data TK V0.2 (AUTO)'!F6:F""), IMPORTRANGE(""https://docs.google.com/spreadsheets/d/1RJrFMGUC-XijmB6MWr0bUJNzuN7BM"&"1j8R_D0vOt0s8I/edit?usp=sharing"", ""'Master Data TK V0.2 (AUTO)'!W6:W""))"),"") | L23: =IFERROR(__xludf.DUMMYFUNCTION("XLOOKUP($C23, IMPORTRANGE(""https://docs.google.com/spreadsheets/d/1RJrFMGUC-XijmB6MWr0bUJNzuN7BM1j8R_D0vOt0s8I/edit?usp=sharing"", ""'Master Data TK V0.2 (AUTO)'!F6:F""), IMPORTRANGE(""https://docs.google.com/spreadsheets/d/1RJrFMGUC-XijmB6MWr0bUJNzuN7BM"&"1j8R_D0vOt0s8I/edit?usp=sharing"", ""'Master Data TK V0.2 (AUTO)'!X6:X""))"),"")
A24: CRO 1 | B24: Regional Sumut 1 | C24: PT Karimun Aromatics Co. Ltd | D24: PT-KAC-01 | E24: {=XLOOKUP(C24,'DATA TK PANEN'!D:D,'DATA TK PANEN'!H:H)} -> 269 | F24: =IFERROR(__xludf.DUMMYFUNCTION("XLOOKUP(C24, IMPORTRANGE(""https://docs.google.com/spreadsheets/d/1RJrFMGUC-XijmB6MWr0bUJNzuN7BM1j8R_D0vOt0s8I/edit?usp=sharing"", ""'Master Data TK V0.2 (AUTO)'!F6:F""), IMPORTRANGE(""https://docs.google.com/spreadsheets/d/1RJrFMGUC-XijmB6MWr0bUJNzuN7BM1"&"j8R_D0vOt0s8I/edit?usp=sharing"", ""'Master Data TK V0.2 (AUTO)'!S6:S""))"),10.0) -> 10 | G24: =IFERROR(__xludf.DUMMYFUNCTION("XLOOKUP($C24, IMPORTRANGE(""https://docs.google.com/spreadsheets/d/1RJrFMGUC-XijmB6MWr0bUJNzuN7BM1j8R_D0vOt0s8I/edit?usp=sharing"", ""'Master Data TK V0.2 (AUTO)'!F6:F""), IMPORTRANGE(""https://docs.google.com/spreadsheets/d/1RJrFMGUC-XijmB6MWr0bUJNzuN7BM"&"1j8R_D0vOt0s8I/edit?usp=sharing"", ""'Master Data TK V0.2 (AUTO)'!T6:T""))"),7.0) -> 7 | H24: =IFERROR(__xludf.DUMMYFUNCTION("XLOOKUP($C24, IMPORTRANGE(""https://docs.google.com/spreadsheets/d/1RJrFMGUC-XijmB6MWr0bUJNzuN7BM1j8R_D0vOt0s8I/edit?usp=sharing"", ""'Master Data TK V0.2 (AUTO)'!F6:F""), IMPORTRANGE(""https://docs.google.com/spreadsheets/d/1RJrFMGUC-XijmB6MWr0bUJNzuN7BM"&"1j8R_D0vOt0s8I/edit?usp=sharing"", ""'Master Data TK V0.2 (AUTO)'!V6:V""))"),10.0) -> 10 | K24: =IFERROR(__xludf.DUMMYFUNCTION("XLOOKUP($C24, IMPORTRANGE(""https://docs.google.com/spreadsheets/d/1RJrFMGUC-XijmB6MWr0bUJNzuN7BM1j8R_D0vOt0s8I/edit?usp=sharing"", ""'Master Data TK V0.2 (AUTO)'!F6:F""), IMPORTRANGE(""https://docs.google.com/spreadsheets/d/1RJrFMGUC-XijmB6MWr0bUJNzuN7BM"&"1j8R_D0vOt0s8I/edit?usp=sharing"", ""'Master Data TK V0.2 (AUTO)'!W6:W""))"),0.0) -> 0 | L24: =IFERROR(__xludf.DUMMYFUNCTION("XLOOKUP($C24, IMPORTRANGE(""https://docs.google.com/spreadsheets/d/1RJrFMGUC-XijmB6MWr0bUJNzuN7BM1j8R_D0vOt0s8I/edit?usp=sharing"", ""'Master Data TK V0.2 (AUTO)'!F6:F""), IMPORTRANGE(""https://docs.google.com/spreadsheets/d/1RJrFMGUC-XijmB6MWr0bUJNzuN7BM"&"1j8R_D0vOt0s8I/edit?usp=sharing"", ""'Master Data TK V0.2 (AUTO)'!X6:X""))"),0.0) -> 0
A25: CRO 1 | B25: Regional Sumut 1 | C25: PT Karya Hevea Indonesia | D25: PT-KHI-01 | E25: {=XLOOKUP(C25,'DATA TK PANEN'!D:D,'DATA TK PANEN'!H:H)} -> 264.84 | F25: =IFERROR(__xludf.DUMMYFUNCTION("XLOOKUP(C25, IMPORTRANGE(""https://docs.google.com/spreadsheets/d/1RJrFMGUC-XijmB6MWr0bUJNzuN7BM1j8R_D0vOt0s8I/edit?usp=sharing"", ""'Master Data TK V0.2 (AUTO)'!F6:F""), IMPORTRANGE(""https://docs.google.com/spreadsheets/d/1RJrFMGUC-XijmB6MWr0bUJNzuN7BM1"&"j8R_D0vOt0s8I/edit?usp=sharing"", ""'Master Data TK V0.2 (AUTO)'!S6:S""))"),15.0) -> 15 | G25: =IFERROR(__xludf.DUMMYFUNCTION("XLOOKUP($C25, IMPORTRANGE(""https://docs.google.com/spreadsheets/d/1RJrFMGUC-XijmB6MWr0bUJNzuN7BM1j8R_D0vOt0s8I/edit?usp=sharing"", ""'Master Data TK V0.2 (AUTO)'!F6:F""), IMPORTRANGE(""https://docs.google.com/spreadsheets/d/1RJrFMGUC-XijmB6MWr0bUJNzuN7BM"&"1j8R_D0vOt0s8I/edit?usp=sharing"", ""'Master Data TK V0.2 (AUTO)'!T6:T""))"),15.0) -> 15 | H25: =IFERROR(__xludf.DUMMYFUNCTION("XLOOKUP($C25, IMPORTRANGE(""https://docs.google.com/spreadsheets/d/1RJrFMGUC-XijmB6MWr0bUJNzuN7BM1j8R_D0vOt0s8I/edit?usp=sharing"", ""'Master Data TK V0.2 (AUTO)'!F6:F""), IMPORTRANGE(""https://docs.google.com/spreadsheets/d/1RJrFMGUC-XijmB6MWr0bUJNzuN7BM"&"1j8R_D0vOt0s8I/edit?usp=sharing"", ""'Master Data TK V0.2 (AUTO)'!V6:V""))"),13.0) -> 13 | K25: =IFERROR(__xludf.DUMMYFUNCTION("XLOOKUP($C25, IMPORTRANGE(""https://docs.google.com/spreadsheets/d/1RJrFMGUC-XijmB6MWr0bUJNzuN7BM1j8R_D0vOt0s8I/edit?usp=sharing"", ""'Master Data TK V0.2 (AUTO)'!F6:F""), IMPORTRANGE(""https://docs.google.com/spreadsheets/d/1RJrFMGUC-XijmB6MWr0bUJNzuN7BM"&"1j8R_D0vOt0s8I/edit?usp=sharing"", ""'Master Data TK V0.2 (AUTO)'!W6:W""))"),1.0) -> 1 | L25: =IFERROR(__xludf.DUMMYFUNCTION("XLOOKUP($C25, IMPORTRANGE(""https://docs.google.com/spreadsheets/d/1RJrFMGUC-XijmB6MWr0bUJNzuN7BM1j8R_D0vOt0s8I/edit?usp=sharing"", ""'Master Data TK V0.2 (AUTO)'!F6:F""), IMPORTRANGE(""https://docs.google.com/spreadsheets/d/1RJrFMGUC-XijmB6MWr0bUJNzuN7BM"&"1j8R_D0vOt0s8I/edit?usp=sharing"", ""'Master Data TK V0.2 (AUTO)'!X6:X""))"),1.0) -> 1
A26: CRO 1 | B26: Regional Sumut 1 | C26: PT Kembang Sepatu Alam Abadi | D26: PT-KSA-02 | E26: {=XLOOKUP(C26,'DATA TK PANEN'!D:D,'DATA TK PANEN'!H:H)} -> 440.4 | F26: =IFERROR(__xludf.DUMMYFUNCTION("XLOOKUP(C26, IMPORTRANGE(""https://docs.google.com/spreadsheets/d/1RJrFMGUC-XijmB6MWr0bUJNzuN7BM1j8R_D0vOt0s8I/edit?usp=sharing"", ""'Master Data TK V0.2 (AUTO)'!F6:F""), IMPORTRANGE(""https://docs.google.com/spreadsheets/d/1RJrFMGUC-XijmB6MWr0bUJNzuN7BM1"&"j8R_D0vOt0s8I/edit?usp=sharing"", ""'Master Data TK V0.2 (AUTO)'!S6:S""))"),26.0) -> 26 | G26: =IFERROR(__xludf.DUMMYFUNCTION("XLOOKUP($C26, IMPORTRANGE(""https://docs.google.com/spreadsheets/d/1RJrFMGUC-XijmB6MWr0bUJNzuN7BM1j8R_D0vOt0s8I/edit?usp=sharing"", ""'Master Data TK V0.2 (AUTO)'!F6:F""), IMPORTRANGE(""https://docs.google.com/spreadsheets/d/1RJrFMGUC-XijmB6MWr0bUJNzuN7BM"&"1j8R_D0vOt0s8I/edit?usp=sharing"", ""'Master Data TK V0.2 (AUTO)'!T6:T""))"),"") | H26: =IFERROR(__xludf.DUMMYFUNCTION("XLOOKUP($C26, IMPORTRANGE(""https://docs.google.com/spreadsheets/d/1RJrFMGUC-XijmB6MWr0bUJNzuN7BM1j8R_D0vOt0s8I/edit?usp=sharing"", ""'Master Data TK V0.2 (AUTO)'!F6:F""), IMPORTRANGE(""https://docs.google.com/spreadsheets/d/1RJrFMGUC-XijmB6MWr0bUJNzuN7BM"&"1j8R_D0vOt0s8I/edit?usp=sharing"", ""'Master Data TK V0.2 (AUTO)'!V6:V""))"),"") | K26: =IFERROR(__xludf.DUMMYFUNCTION("XLOOKUP($C26, IMPORTRANGE(""https://docs.google.com/spreadsheets/d/1RJrFMGUC-XijmB6MWr0bUJNzuN7BM1j8R_D0vOt0s8I/edit?usp=sharing"", ""'Master Data TK V0.2 (AUTO)'!F6:F""), IMPORTRANGE(""https://docs.google.com/spreadsheets/d/1RJrFMGUC-XijmB6MWr0bUJNzuN7BM"&"1j8R_D0vOt0s8I/edit?usp=sharing"", ""'Master Data TK V0.2 (AUTO)'!W6:W""))"),"") | L26: =IFERROR(__xludf.DUMMYFUNCTION("XLOOKUP($C26, IMPORTRANGE(""https://docs.google.com/spreadsheets/d/1RJrFMGUC-XijmB6MWr0bUJNzuN7BM1j8R_D0vOt0s8I/edit?usp=sharing"", ""'Master Data TK V0.2 (AUTO)'!F6:F""), IMPORTRANGE(""https://docs.google.com/spreadsheets/d/1RJrFMGUC-XijmB6MWr0bUJNzuN7BM"&"1j8R_D0vOt0s8I/edit?usp=sharing"", ""'Master Data TK V0.2 (AUTO)'!X6:X""))"),"")
A27: CRO 1 | B27: Regional Sumut 1 | C27: PT Pancasawit Kurniamas | D27: PT-PKA-01 | E27: {=XLOOKUP(C27,'DATA TK PANEN'!D:D,'DATA TK PANEN'!H:H)} -> Tidak Ditemukan | F27: =IFERROR(__xludf.DUMMYFUNCTION("XLOOKUP(C27, IMPORTRANGE(""https://docs.google.com/spreadsheets/d/1RJrFMGUC-XijmB6MWr0bUJNzuN7BM1j8R_D0vOt0s8I/edit?usp=sharing"", ""'Master Data TK V0.2 (AUTO)'!F6:F""), IMPORTRANGE(""https://docs.google.com/spreadsheets/d/1RJrFMGUC-XijmB6MWr0bUJNzuN7BM1"&"j8R_D0vOt0s8I/edit?usp=sharing"", ""'Master Data TK V0.2 (AUTO)'!S6:S""))"),"-") -> - | G27: =IFERROR(__xludf.DUMMYFUNCTION("XLOOKUP($C27, IMPORTRANGE(""https://docs.google.com/spreadsheets/d/1RJrFMGUC-XijmB6MWr0bUJNzuN7BM1j8R_D0vOt0s8I/edit?usp=sharing"", ""'Master Data TK V0.2 (AUTO)'!F6:F""), IMPORTRANGE(""https://docs.google.com/spreadsheets/d/1RJrFMGUC-XijmB6MWr0bUJNzuN7BM"&"1j8R_D0vOt0s8I/edit?usp=sharing"", ""'Master Data TK V0.2 (AUTO)'!T6:T""))"),"-") -> - | H27: =IFERROR(__xludf.DUMMYFUNCTION("XLOOKUP($C27, IMPORTRANGE(""https://docs.google.com/spreadsheets/d/1RJrFMGUC-XijmB6MWr0bUJNzuN7BM1j8R_D0vOt0s8I/edit?usp=sharing"", ""'Master Data TK V0.2 (AUTO)'!F6:F""), IMPORTRANGE(""https://docs.google.com/spreadsheets/d/1RJrFMGUC-XijmB6MWr0bUJNzuN7BM"&"1j8R_D0vOt0s8I/edit?usp=sharing"", ""'Master Data TK V0.2 (AUTO)'!V6:V""))"),"") | K27: =IFERROR(__xludf.DUMMYFUNCTION("XLOOKUP($C27, IMPORTRANGE(""https://docs.google.com/spreadsheets/d/1RJrFMGUC-XijmB6MWr0bUJNzuN7BM1j8R_D0vOt0s8I/edit?usp=sharing"", ""'Master Data TK V0.2 (AUTO)'!F6:F""), IMPORTRANGE(""https://docs.google.com/spreadsheets/d/1RJrFMGUC-XijmB6MWr0bUJNzuN7BM"&"1j8R_D0vOt0s8I/edit?usp=sharing"", ""'Master Data TK V0.2 (AUTO)'!W6:W""))"),"") | L27: =IFERROR(__xludf.DUMMYFUNCTION("XLOOKUP($C27, IMPORTRANGE(""https://docs.google.com/spreadsheets/d/1RJrFMGUC-XijmB6MWr0bUJNzuN7BM1j8R_D0vOt0s8I/edit?usp=sharing"", ""'Master Data TK V0.2 (AUTO)'!F6:F""), IMPORTRANGE(""https://docs.google.com/spreadsheets/d/1RJrFMGUC-XijmB6MWr0bUJNzuN7BM"&"1j8R_D0vOt0s8I/edit?usp=sharing"", ""'Master Data TK V0.2 (AUTO)'!X6:X""))"),"")
A28: CRO 1 | B28: Regional Sumut 1 | C28: PT Paten Alam Lestari | D28: PT-PAL-04 | E28: {=XLOOKUP(C28,'DATA TK PANEN'!D:D,'DATA TK PANEN'!H:H)} -> 0 | F28: =IFERROR(__xludf.DUMMYFUNCTION("XLOOKUP(C28, IMPORTRANGE(""https://docs.google.com/spreadsheets/d/1RJrFMGUC-XijmB6MWr0bUJNzuN7BM1j8R_D0vOt0s8I/edit?usp=sharing"", ""'Master Data TK V0.2 (AUTO)'!F6:F""), IMPORTRANGE(""https://docs.google.com/spreadsheets/d/1RJrFMGUC-XijmB6MWr0bUJNzuN7BM1"&"j8R_D0vOt0s8I/edit?usp=sharing"", ""'Master Data TK V0.2 (AUTO)'!S6:S""))"),"-") -> - | G28: =IFERROR(__xludf.DUMMYFUNCTION("XLOOKUP($C28, IMPORTRANGE(""https://docs.google.com/spreadsheets/d/1RJrFMGUC-XijmB6MWr0bUJNzuN7BM1j8R_D0vOt0s8I/edit?usp=sharing"", ""'Master Data TK V0.2 (AUTO)'!F6:F""), IMPORTRANGE(""https://docs.google.com/spreadsheets/d/1RJrFMGUC-XijmB6MWr0bUJNzuN7BM"&"1j8R_D0vOt0s8I/edit?usp=sharing"", ""'Master Data TK V0.2 (AUTO)'!T6:T""))"),"-") -> - | H28: =IFERROR(__xludf.DUMMYFUNCTION("XLOOKUP($C28, IMPORTRANGE(""https://docs.google.com/spreadsheets/d/1RJrFMGUC-XijmB6MWr0bUJNzuN7BM1j8R_D0vOt0s8I/edit?usp=sharing"", ""'Master Data TK V0.2 (AUTO)'!F6:F""), IMPORTRANGE(""https://docs.google.com/spreadsheets/d/1RJrFMGUC-XijmB6MWr0bUJNzuN7BM"&"1j8R_D0vOt0s8I/edit?usp=sharing"", ""'Master Data TK V0.2 (AUTO)'!V6:V""))"),"") | K28: =IFERROR(__xludf.DUMMYFUNCTION("XLOOKUP($C28, IMPORTRANGE(""https://docs.google.com/spreadsheets/d/1RJrFMGUC-XijmB6MWr0bUJNzuN7BM1j8R_D0vOt0s8I/edit?usp=sharing"", ""'Master Data TK V0.2 (AUTO)'!F6:F""), IMPORTRANGE(""https://docs.google.com/spreadsheets/d/1RJrFMGUC-XijmB6MWr0bUJNzuN7BM"&"1j8R_D0vOt0s8I/edit?usp=sharing"", ""'Master Data TK V0.2 (AUTO)'!W6:W""))"),"") | L28: =IFERROR(__xludf.DUMMYFUNCTION("XLOOKUP($C28, IMPORTRANGE(""https://docs.google.com/spreadsheets/d/1RJrFMGUC-XijmB6MWr0bUJNzuN7BM1j8R_D0vOt0s8I/edit?usp=sharing"", ""'Master Data TK V0.2 (AUTO)'!F6:F""), IMPORTRANGE(""https://docs.google.com/spreadsheets/d/1RJrFMGUC-XijmB6MWr0bUJNzuN7BM"&"1j8R_D0vOt0s8I/edit?usp=sharing"", ""'Master Data TK V0.2 (AUTO)'!X6:X""))"),"")
A29: CRO 1 | B29: Regional Sumut 1 | C29: PT Perkebunan Inti Sawit Subur | D29: PT-PIS-01 | E29: {=XLOOKUP(C29,'DATA TK PANEN'!D:D,'DATA TK PANEN'!H:H)} -> 0 | F29: =IFERROR(__xludf.DUMMYFUNCTION("XLOOKUP(C29, IMPORTRANGE(""https://docs.google.com/spreadsheets/d/1RJrFMGUC-XijmB6MWr0bUJNzuN7BM1j8R_D0vOt0s8I/edit?usp=sharing"", ""'Master Data TK V0.2 (AUTO)'!F6:F""), IMPORTRANGE(""https://docs.google.com/spreadsheets/d/1RJrFMGUC-XijmB6MWr0bUJNzuN7BM1"&"j8R_D0vOt0s8I/edit?usp=sharing"", ""'Master Data TK V0.2 (AUTO)'!S6:S""))"),"-") -> - | G29: =IFERROR(__xludf.DUMMYFUNCTION("XLOOKUP($C29, IMPORTRANGE(""https://docs.google.com/spreadsheets/d/1RJrFMGUC-XijmB6MWr0bUJNzuN7BM1j8R_D0vOt0s8I/edit?usp=sharing"", ""'Master Data TK V0.2 (AUTO)'!F6:F""), IMPORTRANGE(""https://docs.google.com/spreadsheets/d/1RJrFMGUC-XijmB6MWr0bUJNzuN7BM"&"1j8R_D0vOt0s8I/edit?usp=sharing"", ""'Master Data TK V0.2 (AUTO)'!T6:T""))"),"-") -> - | H29: =IFERROR(__xludf.DUMMYFUNCTION("XLOOKUP($C29, IMPORTRANGE(""https://docs.google.com/spreadsheets/d/1RJrFMGUC-XijmB6MWr0bUJNzuN7BM1j8R_D0vOt0s8I/edit?usp=sharing"", ""'Master Data TK V0.2 (AUTO)'!F6:F""), IMPORTRANGE(""https://docs.google.com/spreadsheets/d/1RJrFMGUC-XijmB6MWr0bUJNzuN7BM"&"1j8R_D0vOt0s8I/edit?usp=sharing"", ""'Master Data TK V0.2 (AUTO)'!V6:V""))"),"") | K29: =IFERROR(__xludf.DUMMYFUNCTION("XLOOKUP($C29, IMPORTRANGE(""https://docs.google.com/spreadsheets/d/1RJrFMGUC-XijmB6MWr0bUJNzuN7BM1j8R_D0vOt0s8I/edit?usp=sharing"", ""'Master Data TK V0.2 (AUTO)'!F6:F""), IMPORTRANGE(""https://docs.google.com/spreadsheets/d/1RJrFMGUC-XijmB6MWr0bUJNzuN7BM"&"1j8R_D0vOt0s8I/edit?usp=sharing"", ""'Master Data TK V0.2 (AUTO)'!W6:W""))"),"") | L29: =IFERROR(__xludf.DUMMYFUNCTION("XLOOKUP($C29, IMPORTRANGE(""https://docs.google.com/spreadsheets/d/1RJrFMGUC-XijmB6MWr0bUJNzuN7BM1j8R_D0vOt0s8I/edit?usp=sharing"", ""'Master Data TK V0.2 (AUTO)'!F6:F""), IMPORTRANGE(""https://docs.google.com/spreadsheets/d/1RJrFMGUC-XijmB6MWr0bUJNzuN7BM"&"1j8R_D0vOt0s8I/edit?usp=sharing"", ""'Master Data TK V0.2 (AUTO)'!X6:X""))"),"")
